Workbook

Sheet 1日目 10-31
A1: 1日目 10/31（土）シフト表 営業 10:00〜14:00（14:00までに全組退出）
A2: 黄色のセルに名前を入力してください。1つのセルに1人。例）受付① → 山田 花子
A3: 同じシフトに同じ名前が2回入ると、右の欄に「重複」と表示されます。交代表とスイッチ番は、上の配置表から自動で入ります。
A5: 場所 | B5: 役割 | C5: 仕事内容 | D5: 午前シフト（9:15集合〜12:00交代） | E5: 午後シフト（11:30集合〜片付け） | F5: 午前 重複 | G5: 午後 重複
A6: 受付 | B6: 受付① | C6: 整理券の配布・確認、注意事項の説明、ライトを渡す、ゆるめの判断 | F6: =IF(D6="","",IF(COUNTIF($D$6:$D$20,D6)>1,"重複","")) | G6: =IF(E6="","",IF(COUNTIF($E$6:$E$20,E6)>1,"重複",""))
A7: 受付 | B7: 受付② | C7: 同上。待機列が混んだときの案内 | F7: =IF(D7="","",IF(COUNTIF($D$6:$D$20,D7)>1,"重複","")) | G7: =IF(E7="","",IF(COUNTIF($E$6:$E$20,E7)>1,"重複",""))
A8: 受付の教室 | B8: 待機列・導入係① | C8: 導入動画を流す（前の組が1部屋目に入って1分40秒後）、1部屋目へ送る。スイッチ番を兼ねる | F8: =IF(D8="","",IF(COUNTIF($D$6:$D$20,D8)>1,"重複","")) | G8: =IF(E8="","",IF(COUNTIF($E$6:$E$20,E8)>1,"重複",""))
A9: 受付の教室 | B9: 待機列係② | C9: 待機列の整理、なぞなぞ・掲示の案内 | F9: =IF(D9="","",IF(COUNTIF($D$6:$D$20,D9)>1,"重複","")) | G9: =IF(E9="","",IF(COUNTIF($E$6:$E$20,E9)>1,"重複",""))
A10: 1部屋目 | B10: 花子役A（30分交代） | C10: 生の声（ささやき声）で花子を演じる | F10: =IF(D10="","",IF(COUNTIF($D$6:$D$20,D10)>1,"重複","")) | G10: =IF(E10="","",IF(COUNTIF($E$6:$E$20,E10)>1,"重複",""))
A11: 1部屋目 | B11: 花子役B（30分交代） | C11: 出番でないときはスイッチ番（懐中電灯・インカムを持って待機） | F11: =IF(D11="","",IF(COUNTIF($D$6:$D$20,D11)>1,"重複","")) | G11: =IF(E11="","",IF(COUNTIF($E$6:$E$20,E11)>1,"重複",""))
A12: 1部屋目 | B12: 個室3の係 | C12: ノック返し、時間の合図、リセット時にお守りを置く、インカム | F12: =IF(D12="","",IF(COUNTIF($D$6:$D$20,D12)>1,"重複","")) | G12: =IF(E12="","",IF(COUNTIF($E$6:$E$20,E12)>1,"重複",""))
A13: 2部屋目 | B13: テケテケ役A（30分交代） | C13: 客の後ろからだけ追う・2m以上離れる・客が止まったら止まる | F13: =IF(D13="","",IF(COUNTIF($D$6:$D$20,D13)>1,"重複","")) | G13: =IF(E13="","",IF(COUNTIF($E$6:$E$20,E13)>1,"重複",""))
A14: 2部屋目 | B14: テケテケ役B（30分交代） | C14: 出番でないときはスイッチ番（懐中電灯・インカムを持って待機） | F14: =IF(D14="","",IF(COUNTIF($D$6:$D$20,D14)>1,"重複","")) | G14: =IF(E14="","",IF(COUNTIF($E$6:$E$20,E14)>1,"重複",""))
A15: 2部屋目 | B15: 物音係 | C15: 物音・音声の再生、落ちる足、お供え箱の鈴の確認 | F15: =IF(D15="","",IF(COUNTIF($D$6:$D$20,D15)>1,"重複","")) | G15: =IF(E15="","",IF(COUNTIF($E$6:$E$20,E15)>1,"重複",""))
A16: 2部屋目 | B16: 扉係 | C16: お守りを納めない組への声かけ、扉を開ける | F16: =IF(D16="","",IF(COUNTIF($D$6:$D$20,D16)>1,"重複","")) | G16: =IF(E16="","",IF(COUNTIF($E$6:$E$20,E16)>1,"重複",""))
A17: 3部屋目 | B17: 花子役 | C17: 3つ目の欠片が取られたら（「……もう、どこにも行かせない」の音声が合図）動き出す。歩いて追い、床の印で止まる | F17: =IF(D17="","",IF(COUNTIF($D$6:$D$20,D17)>1,"重複","")) | G17: =IF(E17="","",IF(COUNTIF($E$6:$E$20,E17)>1,"重複",""))
... A20: 全体 | B20: 遊撃・リーダー | C20: 休憩の交代、トラブル対応、お守りの運搬 | F20: =IF(D20="","",IF(COUNTIF($D$6:$D$20,D20)>1,"重複","")) | G20: =IF(E20="","",IF(COUNTIF($E$6:$E$20,E20)>1,"重複",""))
C21: 入力済みの人数（15人で全員） | D21: =COUNTA(D6:D20) -> 0 | E21: =COUNTA(E6:E20) -> 0
A23: 30分交代表（交代はリセットの30秒の間に。インカムで「テケテケ、交代」「花子、交代」）
A24: 時刻 | B24: シフト | C24: 1部屋目 花子（出番） | D24: 1部屋目 スイッチ番（休み） | E24: 2部屋目 テケテケ（出番） | F24: 2部屋目 スイッチ番（休み）
A25: 10:00 | B25: 午前 | C25: =IF($D$10="","（未定）",$D$10) -> （未定） | D25: =IF($D$11="","（未定）",$D$11) -> （未定） | E25: =IF($D$13="","（未定）",$D$13) -> （未定） | F25: =IF($D$14="","（未定）",$D$14) -> （未定）
A26: 10:30 | B26: 午前 | C26: =IF($D$11="","（未定）",$D$11) -> （未定） | D26: =IF($D$10="","（未定）",$D$10) -> （未定） | E26: =IF($D$14="","（未定）",$D$14) -> （未定） | F26: =IF($D$13="","（未定）",$D$13) -> （未定）
A27: 11:00 | B27: 午前 | C27: =IF($D$10="","（未定）",$D$10) -> （未定） | D27: =IF($D$11="","（未定）",$D$11) -> （未定） | E27: =IF($D$13="","（未定）",$D$13) -> （未定） | F27: =IF($D$14="","（未定）",$D$14) -> （未定）
A28: 11:30 | B28: 午前 | C28: =IF($D$11="","（未定）",$D$11) -> （未定） | D28: =IF($D$10="","（未定）",$D$10) -> （未定） | E28: =IF($D$14="","（未定）",$D$14) -> （未定） | F28: =IF($D$13="","（未定）",$D$13) -> （未定）
A29: 12:00 | B29: 午後 | C29: =IF($E$10="","（未定）",$E$10) -> （未定） | D29: =IF($E$11="","（未定）",$E$11) -> （未定） | E29: =IF($E$13="","（未定）",$E$13) -> （未定） | F29: =IF($E$14="","（未定）",$E$14) -> （未定）
A30: 12:30 | B30: 午後 | C30: =IF($E$11="","（未定）",$E$11) -> （未定） | D30: =IF($E$10="","（未定）",$E$10) -> （未定） | E30: =IF($E$14="","（未定）",$E$14) -> （未定） | F30: =IF($E$13="","（未定）",$E$13) -> （未定）
A31: 13:00 | B31: 午後 | C31: =IF($E$10="","（未定）",$E$10) -> （未定） | D31: =IF($E$11="","（未定）",$E$11) -> （未定） | E31: =IF($E$13="","（未定）",$E$13) -> （未定） | F31: =IF($E$14="","（未定）",$E$14) -> （未定）
A32: 13:30 | B32: 午後 | C32: =IF($E$11="","（未定）",$E$11) -> （未定） | D32: =IF($E$10="","（未定）",$E$10) -> （未定） | E32: =IF($E$14="","（未定）",$E$14) -> （未定） | F32: =IF($E$13="","（未定）",$E$13) -> （未定）
A34: スイッチ番（照明スイッチの前に常に1人。懐中電灯を持つ）
A35: 部屋 | B35: スイッチ番 | C35: 午前 | D35: 午後
A36: 受付の教室 | B36: 待機列・導入係① | C36: =IF($D$8="","（未定）",$D$8) -> （未定） | D36: =IF($E$8="","（未定）",$E$8) -> （未定）
A37: 1部屋目 | B37: 花子役の休み番（上の交代表） | C37: 交代表を参照 | D37: 交代表を参照
A38: 2部屋目 | B38: テケテケ役の休み番（上の交代表） | C38: 交代表を参照 | D38: 交代表を参照
A39: 3部屋目 | B39: 光・音係 | C39: =IF($D$18="","（未定）",$D$18) -> （未定） | D39: =IF($E$18="","（未定）",$E$18) -> （未定）
A41: タイムスケジュール
A42: 時刻 | B42: 内容
A43: 9:15 | B43: 全員集合・着替え
A44: 9:30 | B44: 点検（照明・音・電池・インカム、テケテケの通路の掃除、お守りの数）
A45: 9:50 | B45: 係だけで1組分の通し
A46: 9:55 | B46: 午後シフトは解散（11:30まで自由・昼食）
...

Sheet 2日目 11-1
A1: 2日目 11/1（日）シフト表 営業 9:30〜13:00（13:00までに全組退出）
A2: 黄色のセルに名前を入力してください。1つのセルに1人。例）受付① → 山田 花子
A3: 同じシフトに同じ名前が2回入ると、右の欄に「重複」と表示されます。交代表とスイッチ番は、上の配置表から自動で入ります。
A5: 場所 | B5: 役割 | C5: 仕事内容 | D5: 午前シフト（8:45集合〜11:10交代） | E5: 午後シフト（10:40集合〜片付け） | F5: 午前 重複 | G5: 午後 重複
A6: 受付 | B6: 受付① | C6: 整理券の配布・確認、注意事項の説明、ライトを渡す、ゆるめの判断 | F6: =IF(D6="","",IF(COUNTIF($D$6:$D$20,D6)>1,"重複","")) | G6: =IF(E6="","",IF(COUNTIF($E$6:$E$20,E6)>1,"重複",""))
A7: 受付 | B7: 受付② | C7: 同上。待機列が混んだときの案内 | F7: =IF(D7="","",IF(COUNTIF($D$6:$D$20,D7)>1,"重複","")) | G7: =IF(E7="","",IF(COUNTIF($E$6:$E$20,E7)>1,"重複",""))
A8: 受付の教室 | B8: 待機列・導入係① | C8: 導入動画を流す（前の組が1部屋目に入って1分40秒後）、1部屋目へ送る。スイッチ番を兼ねる | F8: =IF(D8="","",IF(COUNTIF($D$6:$D$20,D8)>1,"重複","")) | G8: =IF(E8="","",IF(COUNTIF($E$6:$E$20,E8)>1,"重複",""))
A9: 受付の教室 | B9: 待機列係② | C9: 待機列の整理、なぞなぞ・掲示の案内 | F9: =IF(D9="","",IF(COUNTIF($D$6:$D$20,D9)>1,"重複","")) | G9: =IF(E9="","",IF(COUNTIF($E$6:$E$20,E9)>1,"重複",""))
A10: 1部屋目 | B10: 花子役A（30分交代） | C10: 生の声（ささやき声）で花子を演じる | F10: =IF(D10="","",IF(COUNTIF($D$6:$D$20,D10)>1,"重複","")) | G10: =IF(E10="","",IF(COUNTIF($E$6:$E$20,E10)>1,"重複",""))
A11: 1部屋目 | B11: 花子役B（30分交代） | C11: 出番でないときはスイッチ番（懐中電灯・インカムを持って待機） | F11: =IF(D11="","",IF(COUNTIF($D$6:$D$20,D11)>1,"重複","")) | G11: =IF(E11="","",IF(COUNTIF($E$6:$E$20,E11)>1,"重複",""))
A12: 1部屋目 | B12: 個室3の係 | C12: ノック返し、時間の合図、リセット時にお守りを置く、インカム | F12: =IF(D12="","",IF(COUNTIF($D$6:$D$20,D12)>1,"重複","")) | G12: =IF(E12="","",IF(COUNTIF($E$6:$E$20,E12)>1,"重複",""))
A13: 2部屋目 | B13: テケテケ役A（30分交代） | C13: 客の後ろからだけ追う・2m以上離れる・客が止まったら止まる | F13: =IF(D13="","",IF(COUNTIF($D$6:$D$20,D13)>1,"重複","")) | G13: =IF(E13="","",IF(COUNTIF($E$6:$E$20,E13)>1,"重複",""))
A14: 2部屋目 | B14: テケテケ役B（30分交代） | C14: 出番でないときはスイッチ番（懐中電灯・インカムを持って待機） | F14: =IF(D14="","",IF(COUNTIF($D$6:$D$20,D14)>1,"重複","")) | G14: =IF(E14="","",IF(COUNTIF($E$6:$E$20,E14)>1,"重複",""))
A15: 2部屋目 | B15: 物音係 | C15: 物音・音声の再生、落ちる足、お供え箱の鈴の確認 | F15: =IF(D15="","",IF(COUNTIF($D$6:$D$20,D15)>1,"重複","")) | G15: =IF(E15="","",IF(COUNTIF($E$6:$E$20,E15)>1,"重複",""))
A16: 2部屋目 | B16: 扉係 | C16: お守りを納めない組への声かけ、扉を開ける | F16: =IF(D16="","",IF(COUNTIF($D$6:$D$20,D16)>1,"重複","")) | G16: =IF(E16="","",IF(COUNTIF($E$6:$E$20,E16)>1,"重複",""))
A17: 3部屋目 | B17: 花子役 | C17: 3つ目の欠片が取られたら（「……もう、どこにも行かせない」の音声が合図）動き出す。歩いて追い、床の印で止まる | F17: =IF(D17="","",IF(COUNTIF($D$6:$D$20,D17)>1,"重複","")) | G17: =IF(E17="","",IF(COUNTIF($E$6:$E$20,E17)>1,"重複",""))
... A20: 全体 | B20: 遊撃・リーダー | C20: 休憩の交代、トラブル対応、お守りの運搬 | F20: =IF(D20="","",IF(COUNTIF($D$6:$D$20,D20)>1,"重複","")) | G20: =IF(E20="","",IF(COUNTIF($E$6:$E$20,E20)>1,"重複",""))
C21: 入力済みの人数（15人で全員） | D21: =COUNTA(D6:D20) -> 0 | E21: =COUNTA(E6:E20) -> 0
A23: 30分交代表（交代はリセットの30秒の間に。インカムで「テケテケ、交代」「花子、交代」）
A24: 時刻 | B24: シフト | C24: 1部屋目 花子（出番） | D24: 1部屋目 スイッチ番（休み） | E24: 2部屋目 テケテケ（出番） | F24: 2部屋目 スイッチ番（休み）
A25: 9:30 | B25: 午前 | C25: =IF($D$10="","（未定）",$D$10) -> （未定） | D25: =IF($D$11="","（未定）",$D$11) -> （未定） | E25: =IF($D$13="","（未定）",$D$13) -> （未定） | F25: =IF($D$14="","（未定）",$D$14) -> （未定）
A26: 10:00 | B26: 午前 | C26: =IF($D$11="","（未定）",$D$11) -> （未定） | D26: =IF($D$10="","（未定）",$D$10) -> （未定） | E26: =IF($D$14="","（未定）",$D$14) -> （未定） | F26: =IF($D$13="","（未定）",$D$13) -> （未定）
A27: 10:30 | B27: 午前 | C27: =IF($D$10="","（未定）",$D$10) -> （未定） | D27: =IF($D$11="","（未定）",$D$11) -> （未定） | E27: =IF($D$13="","（未定）",$D$13) -> （未定） | F27: =IF($D$14="","（未定）",$D$14) -> （未定）
A28: 11:00 | B28: 午前 | C28: =IF($D$11="","（未定）",$D$11) -> （未定） | D28: =IF($D$10="","（未定）",$D$10) -> （未定） | E28: =IF($D$14="","（未定）",$D$14) -> （未定） | F28: =IF($D$13="","（未定）",$D$13) -> （未定）
A29: 11:10 | B29: 午後 | C29: =IF($E$10="","（未定）",$E$10) -> （未定） | D29: =IF($E$11="","（未定）",$E$11) -> （未定） | E29: =IF($E$13="","（未定）",$E$13) -> （未定） | F29: =IF($E$14="","（未定）",$E$14) -> （未定）
A30: 11:40 | B30: 午後 | C30: =IF($E$11="","（未定）",$E$11) -> （未定） | D30: =IF($E$10="","（未定）",$E$10) -> （未定） | E30: =IF($E$14="","（未定）",$E$14) -> （未定） | F30: =IF($E$13="","（未定）",$E$13) -> （未定）
A31: 12:10 | B31: 午後 | C31: =IF($E$10="","（未定）",$E$10) -> （未定） | D31: =IF($E$11="","（未定）",$E$11) -> （未定） | E31: =IF($E$13="","（未定）",$E$13) -> （未定） | F31: =IF($E$14="","（未定）",$E$14) -> （未定）
A32: 12:40 | B32: 午後 | C32: =IF($E$11="","（未定）",$E$11) -> （未定） | D32: =IF($E$10="","（未定）",$E$10) -> （未定） | E32: =IF($E$14="","（未定）",$E$14) -> （未定） | F32: =IF($E$13="","（未定）",$E$13) -> （未定）
A34: スイッチ番（照明スイッチの前に常に1人。懐中電灯を持つ）
A35: 部屋 | B35: スイッチ番 | C35: 午前 | D35: 午後
A36: 受付の教室 | B36: 待機列・導入係① | C36: =IF($D$8="","（未定）",$D$8) -> （未定） | D36: =IF($E$8="","（未定）",$E$8) -> （未定）
A37: 1部屋目 | B37: 花子役の休み番（上の交代表） | C37: 交代表を参照 | D37: 交代表を参照
A38: 2部屋目 | B38: テケテケ役の休み番（上の交代表） | C38: 交代表を参照 | D38: 交代表を参照
A39: 3部屋目 | B39: 光・音係 | C39: =IF($D$18="","（未定）",$D$18) -> （未定） | D39: =IF($E$18="","（未定）",$E$18) -> （未定）
A41: タイムスケジュール
A42: 時刻 | B42: 内容
A43: 8:45 | B43: 全員集合・着替え
A44: 9:00 | B44: 点検（1日目の反省会で決めた変更点も確認）
A45: 9:20 | B45: 係だけで1組分の通し
A46: 9:25 | B46: 午後シフトは解散（10:40まで自由）
...

Sheet メンバー一覧
A1: メンバー一覧（名前を入れると、何回シフトに入っているかが自動で出ます）
A2: 黄色のセルに、クラス全員の名前を1行に1人ずつ入れてください。例）山田 花子
A4: 名前 | B4: 1日目の担当数 | C4: 2日目の担当数 | D4: 合計 | E4: 確認
B5: =IF(A5="","",COUNTIF('1日目 10-31'!$D$6:$E$20,A5)) | C5: =IF(A5="","",COUNTIF('2日目 11-1'!$D$6:$E$20,A5)) | D5: =IF(A5="","",B5+C5) | E5: =IF(A5="","",IF(D5=0,"未配置",IF(OR(B5>1,C5>1),"同じ日に2回","")))
B6: =IF(A6="","",COUNTIF('1日目 10-31'!$D$6:$E$20,A6)) | C6: =IF(A6="","",COUNTIF('2日目 11-1'!$D$6:$E$20,A6)) | D6: =IF(A6="","",B6+C6) | E6: =IF(A6="","",IF(D6=0,"未配置",IF(OR(B6>1,C6>1),"同じ日に2回","")))
B7: =IF(A7="","",COUNTIF('1日目 10-31'!$D$6:$E$20,A7)) | C7: =IF(A7="","",COUNTIF('2日目 11-1'!$D$6:$E$20,A7)) | D7: =IF(A7="","",B7+C7) | E7: =IF(A7="","",IF(D7=0,"未配置",IF(OR(B7>1,C7>1),"同じ日に2回","")))
B8: =IF(A8="","",COUNTIF('1日目 10-31'!$D$6:$E$20,A8)) | C8: =IF(A8="","",COUNTIF('2日目 11-1'!$D$6:$E$20,A8)) | D8: =IF(A8="","",B8+C8) | E8: =IF(A8="","",IF(D8=0,"未配置",IF(OR(B8>1,C8>1),"同じ日に2回","")))
B9: =IF(A9="","",COUNTIF('1日目 10-31'!$D$6:$E$20,A9)) | C9: =IF(A9="","",COUNTIF('2日目 11-1'!$D$6:$E$20,A9)) | D9: =IF(A9="","",B9+C9) | E9: =IF(A9="","",IF(D9=0,"未配置",IF(OR(B9>1,C9>1),"同じ日に2回","")))
B10: =IF(A10="","",COUNTIF('1日目 10-31'!$D$6:$E$20,A10)) | C10: =IF(A10="","",COUNTIF('2日目 11-1'!$D$6:$E$20,A10)) | D10: =IF(A10="","",B10+C10) | E10: =IF(A10="","",IF(D10=0,"未配置",IF(OR(B10>1,C10>1),"同じ日に2回","")))
B11: =IF(A11="","",COUNTIF('1日目 10-31'!$D$6:$E$20,A11)) | C11: =IF(A11="","",COUNTIF('2日目 11-1'!$D$6:$E$20,A11)) | D11: =IF(A11="","",B11+C11) | E11: =IF(A11="","",IF(D11=0,"未配置",IF(OR(B11>1,C11>1),"同じ日に2回","")))
B12: =IF(A12="","",COUNTIF('1日目 10-31'!$D$6:$E$20,A12)) | C12: =IF(A12="","",COUNTIF('2日目 11-1'!$D$6:$E$20,A12)) | D12: =IF(A12="","",B12+C12) | E12: =IF(A12="","",IF(D12=0,"未配置",IF(OR(B12>1,C12>1),"同じ日に2回","")))
B13: =IF(A13="","",COUNTIF('1日目 10-31'!$D$6:$E$20,A13)) | C13: =IF(A13="","",COUNTIF('2日目 11-1'!$D$6:$E$20,A13)) | D13: =IF(A13="","",B13+C13) | E13: =IF(A13="","",IF(D13=0,"未配置",IF(OR(B13>1,C13>1),"同じ日に2回","")))
B14: =IF(A14="","",COUNTIF('1日目 10-31'!$D$6:$E$20,A14)) | C14: =IF(A14="","",COUNTIF('2日目 11-1'!$D$6:$E$20,A14)) | D14: =IF(A14="","",B14+C14) | E14: =IF(A14="","",IF(D14=0,"未配置",IF(OR(B14>1,C14>1),"同じ日に2回","")))
B15: =IF(A15="","",COUNTIF('1日目 10-31'!$D$6:$E$20,A15)) | C15: =IF(A15="","",COUNTIF('2日目 11-1'!$D$6:$E$20,A15)) | D15: =IF(A15="","",B15+C15) | E15: =IF(A15="","",IF(D15=0,"未配置",IF(OR(B15>1,C15>1),"同じ日に2回","")))
B16: =IF(A16="","",COUNTIF('1日目 10-31'!$D$6:$E$20,A16)) | C16: =IF(A16="","",COUNTIF('2日目 11-1'!$D$6:$E$20,A16)) | D16: =IF(A16="","",B16+C16) | E16: =IF(A16="","",IF(D16=0,"未配置",IF(OR(B16>1,C16>1),"同じ日に2回","")))
... B54: =IF(A54="","",COUNTIF('1日目 10-31'!$D$6:$E$20,A54)) | C54: =IF(A54="","",COUNTIF('2日目 11-1'!$D$6:$E$20,A54)) | D54: =IF(A54="","",B54+C54) | E54: =IF(A54="","",IF(D54=0,"未配置",IF(OR(B54>1,C54>1),"同じ日に2回","")))

Sheet 役割の説明
A1: 役割の説明と持ち物
A3: 場所 | B3: 役割 | C3: 仕事内容 | D3: インカム | E3: 懐中電灯
A4: 受付 | B4: 受付① | C4: 整理券の配布・確認、注意事項の説明、ライトを渡す、ゆるめの判断 | D4: ○
A5: 受付 | B5: 受付② | C5: 同上。待機列が混んだときの案内
A6: 受付の教室 | B6: 待機列・導入係① | C6: 導入動画を流す（前の組が1部屋目に入って1分40秒後）、1部屋目へ送る。スイッチ番を兼ねる | D6: ○ | E6: ○
A7: 受付の教室 | B7: 待機列係② | C7: 待機列の整理、なぞなぞ・掲示の案内
A8: 1部屋目 | B8: 花子役A（30分交代） | C8: 生の声（ささやき声）で花子を演じる
A9: 1部屋目 | B9: 花子役B（30分交代） | C9: 出番でないときはスイッチ番（懐中電灯・インカムを持って待機） | D9: ○ | E9: ○
A10: 1部屋目 | B10: 個室3の係 | C10: ノック返し、時間の合図、リセット時にお守りを置く、インカム | D10: ○
A11: 2部屋目 | B11: テケテケ役A（30分交代） | C11: 客の後ろからだけ追う・2m以上離れる・客が止まったら止まる
A12: 2部屋目 | B12: テケテケ役B（30分交代） | C12: 出番でないときはスイッチ番（懐中電灯・インカムを持って待機） | D12: ○ | E12: ○
A13: 2部屋目 | B13: 物音係 | C13: 物音・音声の再生、落ちる足、お供え箱の鈴の確認 | D13: ○
A14: 2部屋目 | B14: 扉係 | C14: お守りを納めない組への声かけ、扉を開ける | D14: ○
A15: 3部屋目 | B15: 花子役 | C15: 3つ目の欠片が取られたら（「……もう、どこにも行かせない」の音声が合図）動き出す。歩いて追い、床の印で止まる
A16: 3部屋目 | B16: 光・音係 | C16: 欠片を数えて音声を流す、鏡を光らせる、机を引っ張る、スイッチ番を兼ねる | D16: ○ | E16: ○
A17: 3部屋目・出口 | B17: 出口係 | C17: 出口の案内、ライト回収、鏡をはめられなかった組の案内 | D17: ○
A18: 全体 | B18: 遊撃・リーダー | C18: 休憩の交代、トラブル対応、お守りの運搬 | D18: ○ | E18: ○
A20: ・インカムはイヤホンをつけて使う（客に聞こえないように）
A21: ・花子役・テケテケ役の休み番は、スイッチ番として懐中電灯とインカムを持って待機する
A22: ・「全体、点灯」で、各部屋のスイッチ番がすぐに照明をつける。リタイアのときも同じ
A23: ・インカムの台数は10台の想定。○の役割に優先して渡す
A24: ・この表の役割分担は、これまでの話し合いの内容をもとにした案です。チームで確認して直してください
